Workbook
Name _: NA()
Name _____AGK1: #N/A
Name _____AGK1_1: #N/A
Name _____AGK1_1_1: #N/A
Name _____AGK1_1_1_1: #N/A
Name _____AGK1_1_1_1_1: #N/A
Name _____AGK1_1_1_1_1_1: #N/A
Name _____AGK1_1_1_2: #N/A
Name _____AGK1_1_2: #N/A
Name _____AGK1_1_2_1: #N/A
Name _____AGK1_1_2_1_1: #N/A
Name _____AGK1_1_2_2: #N/A
Name _____AGK1_1_3: #N/A
Name _____AGK1_1_3_1: #N/A
Name _____AGK1_1_3_2: #N/A
Name _____AGK1_1_4: #N/A
Name _____AGK1_1_4_1: #N/A
Name _____AGK1_1_4_2: #N/A
Name _____AGK1_1_5: #N/A
Name _____AGK1_1_5_1: #N/A
Name _____AGK1_1_5_2: #N/A
Name _____AGK1_1_6: #N/A
Name _____AGK1_1_6_1: #N/A
Name _____AGK1_1_6_2: #N/A
Name _____AGK1_1_7: #N/A
Name _____AGK1_1_7_1: #N/A
Name _____AGK1_1_7_2: #N/A
Name _____AGK1_2: #N/A
Name _____AGK1_2_1: #N/A
Name _____AGK1_2_1_1: #N/A
Name _____AGK1_2_2: #N/A
Name _____AGK1_3: #N/A
Name _____AGK1_3_1: #N/A
Name _____AGK1_3_2: #N/A
Name _____AGK1_4: #N/A
Name _____AGK1_4_1: #N/A
Name _____AGK1_4_2: #N/A
Name _____AGK1_5: #N/A
Name _____AGK1_5_1: #N/A
Name _____AGK1_5_2: #N/A
Name _____AGK1_6: #N/A
Name _____AGK1_6_1: #N/A
Name _____AGK1_6_2: #N/A
Name _____AGK1_7: #N/A
Name _____AGK1_7_1: #N/A
Name _____AGK1_7_2: #N/A
Name _____AGK2: #N/A
Name _____AGK2_1: #N/A
Name _____AGK2_1_1: #N/A
Name _____AGK2_1_1_1: #N/A
Name _____AGK2_1_1_1_1: #N/A
Name _____AGK2_1_1_1_1_1: #N/A
Name _____AGK2_1_1_2: #N/A
Name _____AGK2_1_2: #N/A
Name _____AGK2_1_2_1: #N/A
Name _____AGK2_1_2_1_1: #N/A
Name _____AGK2_1_2_2: #N/A
Name _____AGK2_1_3: #N/A
Name _____AGK2_1_3_1: #N/A
Name _____AGK2_1_3_2: #N/A

Sheet İCMAL
B3: POZ NUMARASI | C3: AÇIKLAMA | D3: MALZEME TUTARI (TL) | E3: İŞÇİLİK TUTARI (TL) | F3: GENEL GİDER TUTARI (TL) | G3: TOPLAM TUTAR (TL)
B4: 1.1 | C4: ALÇAK GERİLİM PANOLARI | D4: ='KEŞİF LİSTESİ'!H846 -> 0 | E4: ='KEŞİF LİSTESİ'!I846 -> 0 | F4: ='KEŞİF LİSTESİ'!J846 -> 0 | G4: ='KEŞİF LİSTESİ'!L846 -> 0
B5: 1.2 | C5: KUVVETLİ AKIM KABLOLARI | D5: ='KEŞİF LİSTESİ'!H908 -> 0 | E5: ='KEŞİF LİSTESİ'!I908 -> 0 | F5: ='KEŞİF LİSTESİ'!J908 -> 0 | G5: ='KEŞİF LİSTESİ'!L908 -> 0
B6: 1.3 | C6: KABLO TAŞIYICILARI ve BORULAR | D6: ='KEŞİF LİSTESİ'!H987 -> 0 | E6: ='KEŞİF LİSTESİ'!I987 -> 0 | F6: ='KEŞİF LİSTESİ'!J987 -> 0 | G6: ='KEŞİF LİSTESİ'!L987 -> 0
B7: 1.4 | C7: AYDINLATMA VE PRİZ SORTİLERİ | D7: ='KEŞİF LİSTESİ'!H1014 -> 0 | E7: ='KEŞİF LİSTESİ'!I1014 -> 0 | F7: ='KEŞİF LİSTESİ'!J1014 -> 0 | G7: =+'KEŞİF LİSTESİ'!L1014 -> 0
B8: 1.5 | C8: ANAHTAR VE PRİZLER | D8: ='KEŞİF LİSTESİ'!H1043 -> 0 | E8: ='KEŞİF LİSTESİ'!I1043 -> 0 | F8: ='KEŞİF LİSTESİ'!J1043 -> 0 | G8: =+'KEŞİF LİSTESİ'!L1043 -> 0
B9: 1.6 | C9: ='KEŞİF LİSTESİ'!D1045 -> BUSBAR ve ASKI DESTEK SİSTEMİ | D9: =+'KEŞİF LİSTESİ'!H1165 -> 0 | E9: =+'KEŞİF LİSTESİ'!I1165 -> 0 | F9: =+'KEŞİF LİSTESİ'!J1165 -> 0 | G9: =+'KEŞİF LİSTESİ'!L1165 -> 0
B10: 1.7 | C10: AYDINLATMA ARMATÜRLERİ | D10: İŞVEREN | E10: =+'KEŞİF LİSTESİ'!I1194 -> 0 | F10: =+'KEŞİF LİSTESİ'!J1194 -> 0 | G10: =+'KEŞİF LİSTESİ'!L1194 -> 0
B11: 1.8 | C11: TOPRAKLAMA-YILDIRIMDAN KORUMA TESİSATI | D11: =+'KEŞİF LİSTESİ'!H1217 -> 0 | E11: =+'KEŞİF LİSTESİ'!I1217 -> 0 | F11: =+'KEŞİF LİSTESİ'!J1217 -> 0 | G11: =+'KEŞİF LİSTESİ'!L1217 -> 0
B12: 1.9 | C12: UPS CİHAZI | D12: =+'KEŞİF LİSTESİ'!H1225 -> 0 | E12: =+'KEŞİF LİSTESİ'!I1225 -> 0 | F12: =+'KEŞİF LİSTESİ'!J1225 -> 0 | G12: =+'KEŞİF LİSTESİ'!L1225 -> 0
B13: 2.1 | C13: TELEFON VE DATA SİSTEMİ ve KABLOLAMA | D13: =+'KEŞİF LİSTESİ'!H1269 -> 0 | E13: =+'KEŞİF LİSTESİ'!I1269 -> 0 | F13: =+'KEŞİF LİSTESİ'!J1269 -> 0 | G13: =+'KEŞİF LİSTESİ'!L1269 -> 0
B14: 2.2 | C14: TV SİSTEMİ ve KABLOLAMA | D14: =+'KEŞİF LİSTESİ'!H1302 -> 0 | E14: =+'KEŞİF LİSTESİ'!I1302 -> 0 | F14: =+'KEŞİF LİSTESİ'!J1302 -> 0 | G14: =+'KEŞİF LİSTESİ'!L1302 -> 0
B15: 2.3 | C15: YANGIN İHBAR SİSTEMİ ve KABLOLAMA | D15: =+'KEŞİF LİSTESİ'!H1346 -> 0 | E15: =+'KEŞİF LİSTESİ'!I1346 -> 0 | F15: =+'KEŞİF LİSTESİ'!J1346 -> 0 | G15: =+'KEŞİF LİSTESİ'!L1346 -> 0
B16: 2.4 | C16: SESLENDİRME VE ACİL ANONS SİSTEMİ ve KABLOLAMA | D16: =+'KEŞİF LİSTESİ'!H1373 -> 0 | E16: =+'KEŞİF LİSTESİ'!I1373 -> 0 | F16: =+'KEŞİF LİSTESİ'!J1373 -> 0 | G16: =+'KEŞİF LİSTESİ'!L1373 -> 0
B17: 2.5 | C17: IP CCTV SİSTEMİ ve KABLOLAMA | D17: =+'KEŞİF LİSTESİ'!H1395 -> 0 | E17: =+'KEŞİF LİSTESİ'!I1395 -> 0 | F17: =+'KEŞİF LİSTESİ'!J1395 -> 0 | G17: =+'KEŞİF LİSTESİ'!L1395 -> 0
B18: 2.6 | C18: ARAÇ BARİYER VE PLAKA TANIMA SİSTEMİ ve KABLOLAMA | D18: =+'KEŞİF LİSTESİ'!H1418 -> 0 | E18: =+'KEŞİF LİSTESİ'!I1418 -> 0 | F18: =+'KEŞİF LİSTESİ'!J1418 -> 0 | G18: =+'KEŞİF LİSTESİ'!L1418 -> 0
B19: 2.7 | C19: MEKANİK OTOMASYON İŞLERİ KABLOLAMASI | D19: =+'KEŞİF LİSTESİ'!H1426 -> 0 | E19: =+'KEŞİF LİSTESİ'!I1426 -> 0 | F19: =+'KEŞİF LİSTESİ'!J1426 -> 0 | G19: =+'KEŞİF LİSTESİ'!L1426 -> 0
B20: 2.8 | C20: DİĞER İŞLER ve SOSYAL TESİS YAKIN KEŞİF | D20: ='KEŞİF LİSTESİ'!H1621 -> 0 | E20: ='KEŞİF LİSTESİ'!I1621 -> 0 | F20: ='KEŞİF LİSTESİ'!J1621 -> 0 | G20: =+'KEŞİF LİSTESİ'!L1621 -> 0
B22: GENEL TOPLAM | D22: =SUM(D4:D20) -> 0 | E22: =SUM(E4:E20) -> 0 | F22: =SUM(F4:F20) -> 0 | G22: =SUM(G4:G20) -> 0

Sheet KEŞİF LİSTESİ
C3: NO | D3: AÇIKLAMA | E3: MARKA LİSTESİ | F3: BİRİM | G3: MİKTAR | H3: MALZEME BİRİM FİYATI | I3: İŞÇİLİK BİRİM FİYATI | J3: GENEL GİDER BİRİM FİYATI | K3: TOPLAM BİRİM FİYAT | L3: TOPLAM TUTAR
C4: 1 | D4: KUVVETLİ AKIM SİSTEMLERİ
C5: 1.1 | D5: ALÇAK GERİLİM PANOLARI
D6: ALÇAK GERİLİM PANOLARI Özel teknik şartnamede belirtildiği şekilde ve tek hat şemasında açılımı verilen donanımda ve tüm cihaz ve ölçü aletleri vede % 20 yedek yeri ile birlikte içine alacak ebatta imali olmak üzere profil haline getirilmiş DKP saçtan mamul,önden kontrol edilebilir, kapaklı saç pano tesisi bara mesnet izolatörleri ve pertinaks plakları, iç bağlantı iletkenleri, plastik kablo yolları, cihazların etkilenmesi besleme ve kumanda kablolarının kesitlerine uygun büyüklükte klemensleri giriş ve çıkış kabloları için rakorlar,U profilden montaj kaidesi, bara ve şalt malzeme, hareketli kapakların topraklanması, her nevi ufak malzemesi dahil tablonun montaj işçiliğidir. tablo montajı fiyatına tüm kabloların uç bağlantıları dahil edilecektir. Panolar tekhat şemasına uygun çalışır vaziyette teslim edilecektir. Tüm şalt malzeme Icu kapasitesi proje değerlerine uygun olacaktır. (IEC 61439-1, IEC 60947 standartlarına uygun) Klemensler çift katlı olacaktır. DİKİLİ TİP PANOLAR SİSMİK HALATLARLA TAVAN VE DUVARA SABİTLENECEKTİR,PANO FİYATLARINA DAHİLDİR.
D7: Panolar odaya yerleşecek şekilde uygun ölçülere getirilerek yapılacaktır.
D8: Dikili tip panolarda odaya panolar yerleşecek şekilde gerekirse L Tipi olarak imalat yapılacaktır.Pano birim fiyatına dahildir. Panoların yükseltilmiş kaideleri pano ral kodu ile aynı olacak şekilde sac ile kaplama yapılarak boşlukların gözükmemesi sağlanacaktır. Pano ölçüleri yakın metraj olarak belirtilmiştir.Pano ölçülerinde oluşacak değişikliklerde pano en ve boy uzunluğu baz alınarak m2 hesabı üzerinden birim fiyatı değiştirilecektir.
D9: Panolar Lokal ve Form2b olacaktır.
C11: 1 | D11: 4B.OP1/4B.UPS1 Panosu
C13: 1.1 | D13: DX³ KAKR 4P 80A 30mA A tipi | E13: LEGRAND SCHNEIDER ABB SIEMENS EATON | F13: Ad. | G13: 1 | H13: 0 | I13: 0 | J13: 0 | K13: =+H13+I13+J13 -> 0 | L13: =+G13*K13 -> 0
C14: 1.2 | D14: DX3 3P C 80A 10kA | E14: LEGRAND SCHNEIDER ABB SIEMENS EATON | F14: Ad. | G14: 1 | H14: 0 | I14: 0 | J14: 0 | K14: =+H14+I14+J14 -> 0 | L14: =+G14*K14 -> 0
C15: 1.3 | D15: SİNYAL LAMBASI SARI 220V LED | E15: SİGMA EMAS GWEST | F15: Ad. | G15: 3 | H15: 0 | I15: 0 | J15: 0 | K15: =+H15+I15+J15 -> 0 | L15: =+G15*K15 -> 0
C16: 1.4 | D16: XG6 1P B6 6kA | E16: LEGRAND SCHNEIDER ABB SIEMENS EATON | F16: Ad. | G16: 3 | H16: 0 | I16: 0 | J16: 0 | K16: =+H16+I16+J16 -> 0 | L16: =+G16*K16 -> 0
C17: 1.5 | D17: 10x38 Sigorta Yuvası 3P | E17: GAWE SIGMA | F17: Ad. | G17: 1 | H17: 0 | I17: 0 | J17: 0 | K17: =+H17+I17+J17 -> 0 | L17: =+G17*K17 -> 0
C18: 1.6 | D18: 10x38 32A Silindirik Sigorta Buşonu | E18: GAWE SIGMA | F18: Ad. | G18: 3 | H18: 0 | I18: 0 | J18: 0 | K18: =+H18+I18+J18 -> 0 | L18: =+G18*K18 -> 0
C19: 1.7 | D19: C TİPİ 4 KUTUPLU 40 kA AG PARAFUDR | E19: CITEL LEGRAND OBO | F19: Ad. | G19: 1 | H19: 0 | I19: 0 | J19: 0 | K19: =+H19+I19+J19 -> 0 | L19: =+G19*K19 -> 0
C20: 1.8 | D20: XC10 4P 40A AC 30MA | E20: LEGRAND SCHNEIDER ABB SIEMENS EATON | F20: Ad. | G20: 3 | H20: 0 | I20: 0 | J20: 0 | K20: =+H20+I20+J20 -> 0 | L20: =+G20*K20 -> 0
C21: 1.9 | D21: XG6 1P C16 6kA | E21: LEGRAND SCHNEIDER ABB SIEMENS EATON | F21: Ad. | G21: 22 | H21: 0 | I21: 0 | J21: 0 | K21: =+H21+I21+J21 -> 0 | L21: =+G21*K21 -> 0
C22: 1.10 | D22: XG6 3P C16 6kA | E22: LEGRAND SCHNEIDER ABB SIEMENS EATON | F22: Ad. | G22: 8 | H22: 0 | I22: 0 | J22: 0 | K22: =+H22+I22+J22 -> 0 | L22: =+G22*K22 -> 0
C23: 1.11 | D23: XG6 3P C50 6kA | E23: LEGRAND SCHNEIDER ABB SIEMENS EATON | F23: Ad. | G23: 1 | H23: 0 | I23: 0 | J23: 0 | K23: =+H23+I23+J23 -> 0 | L23: =+G23*K23 -> 0
C24: 1.12 | D24: CTX³ 3P kontaktör 12A 1NA+1NK 230V AC bobinli | E24: LEGRAND SCHNEIDER ABB SIEMENS EATON | F24: Ad. | G24: 3 | H24: 0 | I24: 0 | J24: 0 | K24: =+H24+I24+J24 -> 0 | L24: =+G24*K24 -> 0
... C42: 1.30 | D42: 1200x600x200mm DUVAR TİPİ PANO VE MONTAJI Lokal Pano | E42: AR ETİS FORMPAN BORA GMS GÜL YEKPA PROTECH | F42: Set | G42: 1 | H42: 0 | I42: 0 | J42: 0 | K42: =+H42+I42+J42 -> 0 | L42: =+G42*K42 -> 0
C44: 2 | D44: AS.DP Panosu
C46: 2.1 | D46: XC10 4P 63A 30MA A tip | E46: LEGRAND SCHNEIDER ABB SIEMENS EATON | F46: Ad. | G46: 1 | H46: 0 | I46: 0 | J46: 0 | K46: =+H46+I46+J46 -> 0 | L46: =+G46*K46 -> 0
C47: 2.2 | D47: XG6 3P C50 6kA | E47: LEGRAND SCHNEIDER ABB SIEMENS EATON | F47: Ad. | G47: 1 | H47: 0 | I47: 0 | J47: 0 | K47: =+H47+I47+J47 -> 0 | L47: =+G47*K47 -> 0
C48: 2.3 | D48: SİNYAL LAMBASI SARI 220V LED | E48: SİGMA EMAS GWEST | F48: Ad. | G48: 3 | H48: 0 | I48: 0 | J48: 0 | K48: =+H48+I48+J48 -> 0 | L48: =+G48*K48 -> 0
C49: 2.4 | D49: XG6 1P B6 6kA | E49: LEGRAND SCHNEIDER ABB SIEMENS EATON | F49: Ad. | G49: 3 | H49: 0 | I49: 0 | J49: 0 | K49: =+H49+I49+J49 -> 0 | L49: =+G49*K49 -> 0
C50: 2.5 | D50: 10x38 Sigorta Yuvası 3P | E50: GAWE SIGMA | F50: Ad. | G50: 1 | H50: 0 | I50: 0 | J50: 0 | K50: =+H50+I50+J50 -> 0 | L50: =+G50*K50 -> 0
C51: 2.6 | D51: 10x38 32A Silindirik Sigorta Buşonu | E51: GAWE SIGMA | F51: Ad. | G51: 3 | H51: 0 | I51: 0 | J51: 0 | K51: =+H51+I51+J51 -> 0 | L51: =+G51*K51 -> 0
C52: 2.7 | D52: C TİPİ 4 KUTUPLU 40 kA AG PARAFUDR | E52: CITEL LEGRAND OBO | F52: Ad. | G52: 1 | H52: 0 | I52: 0 | J52: 0 | K52: =+H52+I52+J52 -> 0 | L52: =+G52*K52 -> 0
C53: 2.8 | D53: XC10 4P 25A AC 30MA | E53: LEGRAND SCHNEIDER ABB SIEMENS EATON | F53: Ad. | G53: 4 | H53: 0 | I53: 0 | J53: 0 | K53: =+H53+I53+J53 -> 0 | L53: =+G53*K53 -> 0
C54: 2.9 | D54: XC10 4P 40A AC 30MA | E54: LEGRAND SCHNEIDER ABB SIEMENS EATON | F54: Ad. | G54: 1 | H54: 0 | I54: 0 | J54: 0 | K54: =+H54+I54+J54 -> 0 | L54: =+G54*K54 -> 0
C55: 2.10 | D55: XC10 4P 40A AC 300MA | E55: LEGRAND SCHNEIDER ABB SIEMENS EATON | F55: Ad. | G55: 1 | H55: 0 | I55: 0 | J55: 0 | K55: =+H55+I55+J55 -> 0 | L55: =+G55*K55 -> 0
C56: 2.11 | D56: XG6 1P B6 6kA | E56: LEGRAND SCHNEIDER ABB SIEMENS EATON | F56: Ad. | G56: 6 | H56: 0 | I56: 0 | J56: 0 | K56: =+H56+I56+J56 -> 0 | L56: =+G56*K56 -> 0
C57: 2.12 | D57: XG6 1P B10 6kA | E57: LEGRAND SCHNEIDER ABB SIEMENS EATON | F57: Ad. | G57: 2 | H57: 0 | I57: 0 | J57: 0 | K57: =+H57+I57+J57 -> 0 | L57: =+G57*K57 -> 0
... C71: 2.26 | D71: 1000x700x200mm DUVAR TİPİ PANO VE MONTAJI Lokal Pano | E71: AR ETİS FORMPAN BORA GMS GÜL YEKPA PROTECH | F71: Set | G71: 1 | H71: 0 | I71: 0 | J71: 0 | K71: =+H71+I71+J71 -> 0 | L71: =+G71*K71 -> 0
C73: 3 | D73: AS.UDP Panosu
C75: 3.1 | D75: XG6 3P C25 6kA | E75: LEGRAND SCHNEIDER ABB SIEMENS EATON | F75: Ad. | G75: 1 | H75: 0 | I75: 0 | J75: 0 | K75: =+H75+I75+J75 -> 0 | L75: =+G75*K75 -> 0
C76: 3.2 | D76: XC10 4P 25A 30MA A tip | E76: LEGRAND SCHNEIDER ABB SIEMENS EATON | F76: Ad. | G76: 1 | H76: 0 | I76: 0 | J76: 0 | K76: =+H76+I76+J76 -> 0 | L76: =+G76*K76 -> 0
C77: 3.3 | D77: SİNYAL LAMBASI SARI 220V LED | E77: SİGMA EMAS GWEST | F77: Ad. | G77: 3 | H77: 0 | I77: 0 | J77: 0 | K77: =+H77+I77+J77 -> 0 | L77: =+G77*K77 -> 0
C78: 3.4 | D78: XG6 1P B6 6kA | E78: LEGRAND SCHNEIDER ABB SIEMENS EATON | F78: Ad. | G78: 3 | H78: 0 | I78: 0 | J78: 0 | K78: =+H78+I78+J78 -> 0 | L78: =+G78*K78 -> 0
...
